<?xml version="1.0" encoding="UTF-8"?>
<testng-results skipped="1" failed="1" total="3" passed="1">
  <reporter-output>
  </reporter-output>
  <suite name="Default suite" duration-ms="32" started-at="2019-04-02T17:56:39Z" finished-at="2019-04-02T17:56:39Z">
    <groups>
      <group name="Sanity">
        <method signature="Testing3.homeTest()[pri:1, instance:Testing3@2a2d45ba]" name="homeTest" class="Testing3"/>
        <method signature="Testing3.mainTest()[pri:2, instance:Testing3@2a2d45ba]" name="mainTest" class="Testing3"/>
      </group> <!-- Sanity -->
      <group name="nikul">
        <method signature="Testing3.endTest()[pri:3, instance:Testing3@2a2d45ba]" name="endTest" class="Testing3"/>
      </group> <!-- nikul -->
      <group name="Smoke">
        <method signature="Testing3.mainTest()[pri:2, instance:Testing3@2a2d45ba]" name="mainTest" class="Testing3"/>
      </group> <!-- Smoke -->
    </groups>
    <test name="Default test" duration-ms="32" started-at="2019-04-02T17:56:39Z" finished-at="2019-04-02T17:56:39Z">
      <class name="Testing3">
        <test-method status="FAIL" signature="mainTest()[pri:2, instance:Testing3@2a2d45ba]" name="mainTest" duration-ms="0" started-at="2019-04-02T13:56:39Z" depends-on-methods="Testing3.homeTest" finished-at="2019-04-02T13:56:39Z">
          <exception class="java.lang.AssertionError">
            <message>
              <![CDATA[The following asserts failed:
	Verify element expected [true] but found [false]]]>
            </message>
            <full-stacktrace>
              <![CDATA[java.lang.AssertionError: The following asserts failed:
	Verify element expected [true] but found [false]
	at org.testng.asserts.SoftAssert.assertAll(SoftAssert.java:43)
	at Testing3.mainTest(Testing3.java:24)
	at sun.reflect.NativeMethodAccessorImpl.invoke0(Native Method)
	at sun.reflect.NativeMethodAccessorImpl.invoke(Unknown Source)
	at sun.reflect.DelegatingMethodAccessorImpl.invoke(Unknown Source)
	at java.lang.reflect.Method.invoke(Unknown Source)
	at org.testng.internal.MethodInvocationHelper.invokeMethod(MethodInvocationHelper.java:86)
	at org.testng.internal.Invoker.invokeMethod(Invoker.java:646)
	at org.testng.internal.Invoker.invokeTestMethod(Invoker.java:823)
	at org.testng.internal.Invoker.invokeTestMethods(Invoker.java:1131)
	at org.testng.internal.TestMethodWorker.invokeTestMethods(TestMethodWorker.java:129)
	at org.testng.internal.TestMethodWorker.run(TestMethodWorker.java:112)
	at org.testng.TestRunner.privateRun(TestRunner.java:778)
	at org.testng.TestRunner.run(TestRunner.java:632)
	at org.testng.SuiteRunner.runTest(SuiteRunner.java:366)
	at org.testng.SuiteRunner.runSequentially(SuiteRunner.java:361)
	at org.testng.SuiteRunner.privateRun(SuiteRunner.java:319)
	at org.testng.SuiteRunner.run(SuiteRunner.java:268)
	at org.testng.SuiteRunnerWorker.runSuite(SuiteRunnerWorker.java:52)
	at org.testng.SuiteRunnerWorker.run(SuiteRunnerWorker.java:86)
	at org.testng.TestNG.runSuitesSequentially(TestNG.java:1225)
	at org.testng.TestNG.runSuitesLocally(TestNG.java:1150)
	at org.testng.TestNG.runSuites(TestNG.java:1075)
	at org.testng.TestNG.run(TestNG.java:1047)
	at org.testng.remote.AbstractRemoteTestNG.run(AbstractRemoteTestNG.java:126)
	at org.testng.remote.RemoteTestNG.initAndRun(RemoteTestNG.java:137)
	at org.testng.remote.RemoteTestNG.main(RemoteTestNG.java:58)
]]>
            </full-stacktrace>
          </exception> <!-- java.lang.AssertionError -->
          <reporter-output>
          </reporter-output>
        </test-method> <!-- mainTest -->
        <test-method status="PASS" signature="homeTest()[pri:1, instance:Testing3@2a2d45ba]" name="homeTest" duration-ms="0" started-at="2019-04-02T13:56:39Z" finished-at="2019-04-02T13:56:39Z">
          <reporter-output>
          </reporter-output>
        </test-method> <!-- homeTest -->
        <test-method status="SKIP" signature="endTest()[pri:3, instance:Testing3@2a2d45ba]" name="endTest" duration-ms="0" started-at="2019-04-02T13:56:39Z" depends-on-methods="Testing3.mainTest" finished-at="2019-04-02T13:56:39Z">
          <exception class="java.lang.Throwable">
            <message>
              <![CDATA[Method Testing3.endTest()[pri:3, instance:Testing3@2a2d45ba] depends on not successfully finished methods]]>
            </message>
            <full-stacktrace>
              <![CDATA[java.lang.Throwable: Method Testing3.endTest()[pri:3, instance:Testing3@2a2d45ba] depends on not successfully finished methods
	at org.testng.internal.Invoker.invokeTestMethods(Invoker.java:1040)
	at org.testng.internal.TestMethodWorker.invokeTestMethods(TestMethodWorker.java:129)
	at org.testng.internal.TestMethodWorker.run(TestMethodWorker.java:112)
	at org.testng.TestRunner.privateRun(TestRunner.java:778)
	at org.testng.TestRunner.run(TestRunner.java:632)
	at org.testng.SuiteRunner.runTest(SuiteRunner.java:366)
	at org.testng.SuiteRunner.runSequentially(SuiteRunner.java:361)
	at org.testng.SuiteRunner.privateRun(SuiteRunner.java:319)
	at org.testng.SuiteRunner.run(SuiteRunner.java:268)
	at org.testng.SuiteRunnerWorker.runSuite(SuiteRunnerWorker.java:52)
	at org.testng.SuiteRunnerWorker.run(SuiteRunnerWorker.java:86)
	at org.testng.TestNG.runSuitesSequentially(TestNG.java:1225)
	at org.testng.TestNG.runSuitesLocally(TestNG.java:1150)
	at org.testng.TestNG.runSuites(TestNG.java:1075)
	at org.testng.TestNG.run(TestNG.java:1047)
	at org.testng.remote.AbstractRemoteTestNG.run(AbstractRemoteTestNG.java:126)
	at org.testng.remote.RemoteTestNG.initAndRun(RemoteTestNG.java:137)
	at org.testng.remote.RemoteTestNG.main(RemoteTestNG.java:58)
]]>
            </full-stacktrace>
          </exception> <!-- java.lang.Throwable -->
          <reporter-output>
          </reporter-output>
        </test-method> <!-- endTest -->
      </class> <!-- Testing3 -->
    </test> <!-- Default test -->
  </suite> <!-- Default suite -->
</testng-results>
